<?xml version="1.0"?>
<robot xmlns:xacro="http://www.ros.org/wiki/xacro">

    <property name="M_PI" value="3.1415926535897931" />
    <property name="DEG2RAD" value="0.01745329251994329577" />

    <xacro:macro name="single_joint_robot" params="name xposition yposition">

    <joint name="${name}_joint_0" type="fixed">
        <parent link="world"/>
        <child link="${name}_link_0"/>
        <origin rpy="0 0 0" xyz="${xposition} ${yposition} 0" />
    </joint>
    
    <link name="${name}_link_0">
        <visual>
            <geometry>
                <cylinder length="0.6" radius="0.2"/>
            </geometry>
            <material name="gray">
                <color rgba="0.5 0.5 0.5 1"/>
            </material>
        </visual>
    </link>

    <joint name="${name}_joint_1" type="revolute">
        <origin xyz="0 0 0.35" rpy="${M_PI/2} 0 0"/>
        <parent link="${name}_link_0"/>
        <child link="${name}_link_1"/>
        <limit effort="30" velocity="1.0" lower="-${M_PI}" upper="${M_PI}" />
        <axis xyz="0 1 0"/>
    </joint>

    <link name="${name}_link_1">
        <visual>
            <origin xyz="0 0 0.35" rpy="0 0 0"/>
            <geometry>
                <box size="0.1 0.1 0.7" />
            </geometry>
            <material name="red">
                <color rgba="0.5 0.0 0.0 1"/>
            </material>
        </visual>
    </link>

    <joint name="${name}_end_efector_joint" type="fixed">
        <origin xyz="0 0 0.7" rpy="${M_PI/2} 0 0"/>
        <parent link="${name}_link_1"/>
        <child link="${name}_end_effector"/>
    </joint>

    <link name="${name}_end_effector" />

    </xacro:macro>
    
</robot>
