<?xml version="1.0"?>
<!--FILL IN THE BLANKS-->
<robot name="msd3d" xmlns:xacro="http://www.ros.org/wiki/xacro">

  <property name="M_PI" value="3.1415926535897931" />
  <property name="DEG2RAD" value="0.01745329251994329577" />
  
  <link name="world" />
  
  <joint name="joint_0" type="fixed">
    <parent link="world"/>
    <child link="link_0"/>
    <origin rpy="0 0 0" xyz="0 0 0" />
  </joint>
  
  <link name="link_0">
   <visual>
    <geometry>
      <mesh filename="package://msd3dof_description/meshes/Link0.stl"/>
    </geometry>
    <origin rpy="3.1416 0 1.57079632679" xyz="0 0 0" />
    <material name="grey">
      <color rgba="0.8 0.8 0.8 1"/>
    </material>
   </visual>
  </link>

  <joint name="joint_1" type="prismatic">
    <axis xyz="0 0 -1"/>
    <limit effort="30" velocity="1.0" lower="0.02" upper="0.1"/>
    <parent link="link_0"/>
    <child link="link_1"/>
    <origin rpy="0 0 0" xyz="0 0 -0.5"/>
  </joint>


  <link name="link_1">
   <visual>
    <geometry>
      <mesh filename="package://msd3dof_description/meshes/Link1B.stl"/>
    </geometry>
    <origin rpy="0 0 0" xyz="0 0 0" />
    <material name="grey">
      <color rgba="0.8 0.8 0.8 1"/>
    </material>
   </visual>
  </link>


  <joint name="joint_2" type="revolute">
    <axis xyz="0 -1 0"/>
    <limit effort="30" velocity="1.0" lower="-1.57079632679" upper="1.57079632679"/>
    <parent link="link_1"/>
    <child link="link_2"/>
    <origin rpy="0 0 0" xyz="0 0 -1.075"/>
  </joint>

  <link name="link_2">
   <visual>
    <geometry>
      <mesh filename="package://msd3dof_description/meshes/Link2B.stl"/>
    </geometry>
    <origin rpy="1.57079632679 0 0" xyz="0 0 0" />
    <material name="grey">
      <color rgba="0.8 0.8 0.8 1"/>
    </material>
   </visual>
  </link>

  <joint name="joint_3" type="revolute">
    <axis xyz="0 -1 0"/>
    <limit effort="30" velocity="1.0" lower="-1.57079632679" upper="1.57079632679"/>
    <parent link="link_2"/>
    <child link="link_3"/>
    <origin rpy="0 0 0" xyz="0 0 -1.075"/>
  </joint>

  <link name="link_3">
   <visual>
    <geometry>
      <mesh filename="package://msd3dof_description/meshes/Link2B.stl"/>
    </geometry>
    <origin rpy="1.57079632679 0 0" xyz="0 0 0" />
    <material name="grey">
      <color rgba="0.8 0.8 0.8 1"/>
    </material>
   </visual>
  </link>

  <joint name="end_efector_joint" type="fixed">
    <parent link="link_3"/>
    <child link="end_effector"/>
    <origin rpy="0 0 0" xyz="0 0 -1.075"/>
  </joint>
  
  <link name="end_effector" />

</robot>
